Workbook
Name AccessLevelList: Lookup_Codes!$I$2:$I$10
Name AccPrefix: Settings!$B$8
Name AcqTypeList: Lookup_Codes!$K$2:$K$10
Name AuthorCodeLen: Settings!$B$9
Name CirculationList: Lookup_Codes!$G$2:$G$10
Name CollectionName: Settings!$B$5
Name ConditionList: Lookup_Codes!$F$2:$F$10
Name DefaultLang: Settings!$B$6
Name DigitisationList: Lookup_Codes!$M$2:$M$10
Name FormatList: Lookup_Codes!$D$2:$D$30
Name FrequencyList: Lookup_Codes!$L$2:$L$12
Name GenreList: Lookup_Codes!$B$2:$B$15
Name LanguageList: Lookup_Codes!$C$2:$C$10
Name LibraryName: Settings!$B$4
Name LoanPeriod: Settings!$B$7
Name LocationTypeList: Lookup_Codes!$H$2:$H$10
Name MembershipList: Lookup_Codes!$O$2:$O$10
Name MemberStatusList: Lookup_Codes!$P$2:$P$6
Name OCRStatusList: Lookup_Codes!$E$2:$E$10
Name PhysDigiList: Lookup_Codes!$N$2:$N$5
Name PreservationList: Lookup_Codes!$R$2:$R$6
Name ReadingStatusList: Lookup_Codes!$Q$2:$Q$6
Name ResourceTypeList: Lookup_Codes!$A$2:$A$30
Name RightsList: Lookup_Codes!$J$2:$J$10

Sheet README
B1: Personal Library Manager & Digital Archive
B2: Version 2.0 — Excel Application
B3: Excel is the primary structured-data and metadata layer. The HTML application is a separate presentation/discovery/printing layer.
B4: Try the HTML application
B5: Quick Start
B6: 1. Open the Settings sheet and set your library name, loan period, and defaults.
B7: 2. Open the Catalog sheet. Fill in Accession Number, Title, Creator, Type, Genre, Language, Location Type, and Location Identifier. Item ID, Author Code, Call Number, and Circulation Status are generated automatically.
B8: 3. Use the Digital_Catalog sheet for PDFs, images, audio, video, datasets, and other digital resources.
B9: 4. Use the Archive sheet for physical and digital archival objects.
B10: 5. Record loans in the Circulation sheet. The Catalog's Circulation Status updates automatically.
B11: 6. Monitor completeness and issues on the Dashboard and Data_Quality sheets.
B12: Worksheet Guide
... B54: e-mail me

Sheet Catalog
A1: Item ID | B1: Accession Number | C1: Call Number | D1: Title | E1: Subtitle | F1: Creator | G1: Author Code Override | H1: Author Code | I1: Editor | J1: Translator | K1: Type | L1: Genre | M1: Language | N1: Volume | O1: Edition | P1: Publisher | Q1: Publication Place | R1: Publication Year | S1: ISBN | T1: ISSN | U1: Pages | V1: Series | W1: Location Type | X1: Location Identifier | Y1: Condition | Z1: Circulation Status | AA1: Acquisition Date | AB1: Acquisition Type | AC1: Price | AD1: Donor/Vendor | AE1: Notes | AF1: Rights | AG1: Description
A2: =IF(ISBLANK(D2),"",ROW()-1) -> 1 | B2: ACC-0001 | C2: =IF(ISBLANK(D2),"",MID(K2,SEARCH("(",K2)+1,SEARCH(")",K2)-SEARCH("(",K2)-1)&"-"&MID(L2,SEARCH("(",L2)+1,SEARCH(")",L2)-SEARCH("(",L2)-1)&"-"&H2&"-"&TEXT(A2,"000")&IF(ISBLANK(N2),"","-"&SUBSTITUTE(N2," ",""))) -> FIC-LIT-TAG-001-Vol1 | D2: Rabindra Rachanabali | E2: Vol 1 | F2: Rabindranath Tagore | H2: =IF(ISBLANK(F2),"",IF(G2<>"",UPPER(TRIM(G2)),IF(ISNUMBER(SEARCH(" ",TRIM(F2))),UPPER(LEFT(TRIM(RIGHT(SUBSTITUTE(TRIM(F2)," ",REPT(" ",100)),100)),Settings!$B$9)),UPPER(LEFT(TRIM(F2),Settings!$B$9))))) -> TAG | K2: Fiction (FIC) | L2: Literature (LIT) | M2: Bengali | N2: Vol 1 | W2: Shelf | X2: A2 | Y2: Good | Z2: =IF(ISBLANK(D2),"",IF(COUNTIFS(Circulation!$B$2:$B$500,A2,Circulation!$H$2:$H$500,"Active")>0,"On Loan","Available")) -> Available
A3: =IF(ISBLANK(D3),"",ROW()-1) -> 2 | B3: ACC-0002 | C3: =IF(ISBLANK(D3),"",MID(K3,SEARCH("(",K3)+1,SEARCH(")",K3)-SEARCH("(",K3)-1)&"-"&MID(L3,SEARCH("(",L3)+1,SEARCH(")",L3)-SEARCH("(",L3)-1)&"-"&H3&"-"&TEXT(A3,"000")&IF(ISBLANK(N3),"","-"&SUBSTITUTE(N3," ",""))) -> FIC-LIT-TAG-002-Vol2 | D3: Rabindra Rachanabali | E3: Vol 2 | F3: Rabindranath Tagore | H3: =IF(ISBLANK(F3),"",IF(G3<>"",UPPER(TRIM(G3)),IF(ISNUMBER(SEARCH(" ",TRIM(F3))),UPPER(LEFT(TRIM(RIGHT(SUBSTITUTE(TRIM(F3)," ",REPT(" ",100)),100)),Settings!$B$9)),UPPER(LEFT(TRIM(F3),Settings!$B$9))))) -> TAG | K3: Fiction (FIC) | L3: Literature (LIT) | M3: Bengali | N3: Vol 2 | W3: Shelf | X3: A2 | Y3: Good | Z3: =IF(ISBLANK(D3),"",IF(COUNTIFS(Circulation!$B$2:$B$500,A3,Circulation!$H$2:$H$500,"Active")>0,"On Loan","Available")) -> Available
A4: =IF(ISBLANK(D4),"",ROW()-1) -> 3 | B4: ACC-0003 | C4: =IF(ISBLANK(D4),"",MID(K4,SEARCH("(",K4)+1,SEARCH(")",K4)-SEARCH("(",K4)-1)&"-"&MID(L4,SEARCH("(",L4)+1,SEARCH(")",L4)-SEARCH("(",L4)-1)&"-"&H4&"-"&TEXT(A4,"000")&IF(ISBLANK(N4),"","-"&SUBSTITUTE(N4," ",""))) -> FIC-LIT-TAG-003-Vol3 | D4: Rabindra Rachanabali | E4: Vol 3 | F4: Rabindranath Tagore | H4: =IF(ISBLANK(F4),"",IF(G4<>"",UPPER(TRIM(G4)),IF(ISNUMBER(SEARCH(" ",TRIM(F4))),UPPER(LEFT(TRIM(RIGHT(SUBSTITUTE(TRIM(F4)," ",REPT(" ",100)),100)),Settings!$B$9)),UPPER(LEFT(TRIM(F4),Settings!$B$9))))) -> TAG | K4: Fiction (FIC) | L4: Literature (LIT) | M4: Bengali | N4: Vol 3 | W4: Shelf | X4: A2 | Y4: Good | Z4: =IF(ISBLANK(D4),"",IF(COUNTIFS(Circulation!$B$2:$B$500,A4,Circulation!$H$2:$H$500,"Active")>0,"On Loan","Available")) -> Available
A5: =IF(ISBLANK(D5),"",ROW()-1) -> 4 | B5: ACC-0004 | C5: =IF(ISBLANK(D5),"",MID(K5,SEARCH("(",K5)+1,SEARCH(")",K5)-SEARCH("(",K5)-1)&"-"&MID(L5,SEARCH("(",L5)+1,SEARCH(")",L5)-SEARCH("(",L5)-1)&"-"&H5&"-"&TEXT(A5,"000")&IF(ISBLANK(N5),"","-"&SUBSTITUTE(N5," ",""))) -> FIC-LIT-TAG-004-Vol4 | D5: Rabindra Rachanabali | E5: Vol 4 | F5: Rabindranath Tagore | H5: =IF(ISBLANK(F5),"",IF(G5<>"",UPPER(TRIM(G5)),IF(ISNUMBER(SEARCH(" ",TRIM(F5))),UPPER(LEFT(TRIM(RIGHT(SUBSTITUTE(TRIM(F5)," ",REPT(" ",100)),100)),Settings!$B$9)),UPPER(LEFT(TRIM(F5),Settings!$B$9))))) -> TAG | K5: Fiction (FIC) | L5: Literature (LIT) | M5: Bengali | N5: Vol 4 | W5: Shelf | X5: A2 | Y5: Good | Z5: =IF(ISBLANK(D5),"",IF(COUNTIFS(Circulation!$B$2:$B$500,A5,Circulation!$H$2:$H$500,"Active")>0,"On Loan","Available")) -> Available
A6: =IF(ISBLANK(D6),"",ROW()-1) -> 5 | B6: ACC-0005 | C6: =IF(ISBLANK(D6),"",MID(K6,SEARCH("(",K6)+1,SEARCH(")",K6)-SEARCH("(",K6)-1)&"-"&MID(L6,SEARCH("(",L6)+1,SEARCH(")",L6)-SEARCH("(",L6)-1)&"-"&H6&"-"&TEXT(A6,"000")&IF(ISBLANK(N6),"","-"&SUBSTITUTE(N6," ",""))) -> FIC-LIT-TAG-005-Vol5 | D6: Rabindra Rachanabali | E6: Vol 5 | F6: Rabindranath Tagore | H6: =IF(ISBLANK(F6),"",IF(G6<>"",UPPER(TRIM(G6)),IF(ISNUMBER(SEARCH(" ",TRIM(F6))),UPPER(LEFT(TRIM(RIGHT(SUBSTITUTE(TRIM(F6)," ",REPT(" ",100)),100)),Settings!$B$9)),UPPER(LEFT(TRIM(F6),Settings!$B$9))))) -> TAG | K6: Fiction (FIC) | L6: Literature (LIT) | M6: Bengali | N6: Vol 5 | W6: Shelf | X6: A2 | Y6: Good | Z6: =IF(ISBLANK(D6),"",IF(COUNTIFS(Circulation!$B$2:$B$500,A6,Circulation!$H$2:$H$500,"Active")>0,"On Loan","Available")) -> Available
A7: =IF(ISBLANK(D7),"",ROW()-1) -> 6 | B7: ACC-0006 | C7: =IF(ISBLANK(D7),"",MID(K7,SEARCH("(",K7)+1,SEARCH(")",K7)-SEARCH("(",K7)-1)&"-"&MID(L7,SEARCH("(",L7)+1,SEARCH(")",L7)-SEARCH("(",L7)-1)&"-"&H7&"-"&TEXT(A7,"000")&IF(ISBLANK(N7),"","-"&SUBSTITUTE(N7," ",""))) -> FIC-LIT-TAG-006-Vol6 | D7: Rabindra Rachanabali | E7: Vol 6 | F7: Rabindranath Tagore | H7: =IF(ISBLANK(F7),"",IF(G7<>"",UPPER(TRIM(G7)),IF(ISNUMBER(SEARCH(" ",TRIM(F7))),UPPER(LEFT(TRIM(RIGHT(SUBSTITUTE(TRIM(F7)," ",REPT(" ",100)),100)),Settings!$B$9)),UPPER(LEFT(TRIM(F7),Settings!$B$9))))) -> TAG | K7: Fiction (FIC) | L7: Literature (LIT) | M7: Bengali | N7: Vol 6 | W7: Shelf | X7: A2 | Y7: Good | Z7: =IF(ISBLANK(D7),"",IF(COUNTIFS(Circulation!$B$2:$B$500,A7,Circulation!$H$2:$H$500,"Active")>0,"On Loan","Available")) -> Available
A8: =IF(ISBLANK(D8),"",ROW()-1) -> 7 | B8: ACC-0007 | C8: =IF(ISBLANK(D8),"",MID(K8,SEARCH("(",K8)+1,SEARCH(")",K8)-SEARCH("(",K8)-1)&"-"&MID(L8,SEARCH("(",L8)+1,SEARCH(")",L8)-SEARCH("(",L8)-1)&"-"&H8&"-"&TEXT(A8,"000")&IF(ISBLANK(N8),"","-"&SUBSTITUTE(N8," ",""))) -> FIC-LIT-TAG-007-Vol7 | D8: Rabindra Rachanabali | E8: Vol 7 | F8: Rabindranath Tagore | H8: =IF(ISBLANK(F8),"",IF(G8<>"",UPPER(TRIM(G8)),IF(ISNUMBER(SEARCH(" ",TRIM(F8))),UPPER(LEFT(TRIM(RIGHT(SUBSTITUTE(TRIM(F8)," ",REPT(" ",100)),100)),Settings!$B$9)),UPPER(LEFT(TRIM(F8),Settings!$B$9))))) -> TAG | K8: Fiction (FIC) | L8: Literature (LIT) | M8: Bengali | N8: Vol 7 | W8: Shelf | X8: A2 | Y8: Good | Z8: =IF(ISBLANK(D8),"",IF(COUNTIFS(Circulation!$B$2:$B$500,A8,Circulation!$H$2:$H$500,"Active")>0,"On Loan","Available")) -> Available
A9: =IF(ISBLANK(D9),"",ROW()-1) -> 8 | B9: ACC-0008 | C9: =IF(ISBLANK(D9),"",MID(K9,SEARCH("(",K9)+1,SEARCH(")",K9)-SEARCH("(",K9)-1)&"-"&MID(L9,SEARCH("(",L9)+1,SEARCH(")",L9)-SEARCH("(",L9)-1)&"-"&H9&"-"&TEXT(A9,"000")&IF(ISBLANK(N9),"","-"&SUBSTITUTE(N9," ",""))) -> FIC-LIT-TAG-008-Vol8 | D9: Rabindra Rachanabali | E9: Vol 8 | F9: Rabindranath Tagore | H9: =IF(ISBLANK(F9),"",IF(G9<>"",UPPER(TRIM(G9)),IF(ISNUMBER(SEARCH(" ",TRIM(F9))),UPPER(LEFT(TRIM(RIGHT(SUBSTITUTE(TRIM(F9)," ",REPT(" ",100)),100)),Settings!$B$9)),UPPER(LEFT(TRIM(F9),Settings!$B$9))))) -> TAG | K9: Fiction (FIC) | L9: Literature (LIT) | M9: Bengali | N9: Vol 8 | W9: Shelf | X9: A2 | Y9: Good | Z9: =IF(ISBLANK(D9),"",IF(COUNTIFS(Circulation!$B$2:$B$500,A9,Circulation!$H$2:$H$500,"Active")>0,"On Loan","Available")) -> Available
A10: =IF(ISBLANK(D10),"",ROW()-1) -> 9 | B10: ACC-0009 | C10: =IF(ISBLANK(D10),"",MID(K10,SEARCH("(",K10)+1,SEARCH(")",K10)-SEARCH("(",K10)-1)&"-"&MID(L10,SEARCH("(",L10)+1,SEARCH(")",L10)-SEARCH("(",L10)-1)&"-"&H10&"-"&TEXT(A10,"000")&IF(ISBLANK(N10),"","-"&SUBSTITUTE(N10," ",""))) -> FIC-LIT-TAG-009-Vol9 | D10: Rabindra Rachanabali | E10: Vol 9 | F10: Rabindranath Tagore | H10: =IF(ISBLANK(F10),"",IF(G10<>"",UPPER(TRIM(G10)),IF(ISNUMBER(SEARCH(" ",TRIM(F10))),UPPER(LEFT(TRIM(RIGHT(SUBSTITUTE(TRIM(F10)," ",REPT(" ",100)),100)),Settings!$B$9)),UPPER(LEFT(TRIM(F10),Settings!$B$9))))) -> TAG | K10: Fiction (FIC) | L10: Literature (LIT) | M10: Bengali | N10: Vol 9 | W10: Shelf | X10: A1 | Y10: Good | Z10: =IF(ISBLANK(D10),"",IF(COUNTIFS(Circulation!$B$2:$B$500,A10,Circulation!$H$2:$H$500,"Active")>0,"On Loan","Available")) -> Available
A11: =IF(ISBLANK(D11),"",ROW()-1) -> 10 | B11: ACC-0010 | C11: =IF(ISBLANK(D11),"",MID(K11,SEARCH("(",K11)+1,SEARCH(")",K11)-SEARCH("(",K11)-1)&"-"&MID(L11,SEARCH("(",L11)+1,SEARCH(")",L11)-SEARCH("(",L11)-1)&"-"&H11&"-"&TEXT(A11,"000")&IF(ISBLANK(N11),"","-"&SUBSTITUTE(N11," ",""))) -> FIC-LIT-TAG-010-Vol10 | D11: Rabindra Rachanabali | E11: Vol 10 | F11: Rabindranath Tagore | H11: =IF(ISBLANK(F11),"",IF(G11<>"",UPPER(TRIM(G11)),IF(ISNUMBER(SEARCH(" ",TRIM(F11))),UPPER(LEFT(TRIM(RIGHT(SUBSTITUTE(TRIM(F11)," ",REPT(" ",100)),100)),Settings!$B$9)),UPPER(LEFT(TRIM(F11),Settings!$B$9))))) -> TAG | K11: Fiction (FIC) | L11: Literature (LIT) | M11: Bengali | N11: Vol 10 | W11: Shelf | X11: A1 | Y11: Good | Z11: =IF(ISBLANK(D11),"",IF(COUNTIFS(Circulation!$B$2:$B$500,A11,Circulation!$H$2:$H$500,"Active")>0,"On Loan","Available")) -> Available
A12: =IF(ISBLANK(D12),"",ROW()-1) -> 11 | B12: ACC-0011 | C12: =IF(ISBLANK(D12),"",MID(K12,SEARCH("(",K12)+1,SEARCH(")",K12)-SEARCH("(",K12)-1)&"-"&MID(L12,SEARCH("(",L12)+1,SEARCH(")",L12)-SEARCH("(",L12)-1)&"-"&H12&"-"&TEXT(A12,"000")&IF(ISBLANK(N12),"","-"&SUBSTITUTE(N12," ",""))) -> FIC-LIT-TAG-011-Vol11 | D12: Rabindra Rachanabali | E12: Vol 11 | F12: Rabindranath Tagore | H12: =IF(ISBLANK(F12),"",IF(G12<>"",UPPER(TRIM(G12)),IF(ISNUMBER(SEARCH(" ",TRIM(F12))),UPPER(LEFT(TRIM(RIGHT(SUBSTITUTE(TRIM(F12)," ",REPT(" ",100)),100)),Settings!$B$9)),UPPER(LEFT(TRIM(F12),Settings!$B$9))))) -> TAG | K12: Fiction (FIC) | L12: Literature (LIT) | M12: Bengali | N12: Vol 11 | W12: Shelf | X12: A1 | Y12: Good | Z12: =IF(ISBLANK(D12),"",IF(COUNTIFS(Circulation!$B$2:$B$500,A12,Circulation!$H$2:$H$500,"Active")>0,"On Loan","Available")) -> Available
A13: =IF(ISBLANK(D13),"",ROW()-1) -> 12 | B13: ACC-0012 | C13: =IF(ISBLANK(D13),"",MID(K13,SEARCH("(",K13)+1,SEARCH(")",K13)-SEARCH("(",K13)-1)&"-"&MID(L13,SEARCH("(",L13)+1,SEARCH(")",L13)-SEARCH("(",L13)-1)&"-"&H13&"-"&TEXT(A13,"000")&IF(ISBLANK(N13),"","-"&SUBSTITUTE(N13," ",""))) -> FIC-LIT-TAG-012-Vol12 | D13: Rabindra Rachanabali | E13: Vol 12 | F13: Rabindranath Tagore | H13: =IF(ISBLANK(F13),"",IF(G13<>"",UPPER(TRIM(G13)),IF(ISNUMBER(SEARCH(" ",TRIM(F13))),UPPER(LEFT(TRIM(RIGHT(SUBSTITUTE(TRIM(F13)," ",REPT(" ",100)),100)),Settings!$B$9)),UPPER(LEFT(TRIM(F13),Settings!$B$9))))) -> TAG | K13: Fiction (FIC) | L13: Literature (LIT) | M13: Bengali | N13: Vol 12 | W13: Shelf | X13: A1 | Y13: Good | Z13: =IF(ISBLANK(D13),"",IF(COUNTIFS(Circulation!$B$2:$B$500,A13,Circulation!$H$2:$H$500,"Active")>0,"On Loan","Available")) -> Available
... A20: =IF(ISBLANK(D20),"",ROW()-1) -> 19 | B20: ACC-0019 | C20: =IF(ISBLANK(D20),"",MID(K20,SEARCH("(",K20)+1,SEARCH(")",K20)-SEARCH("(",K20)-1)&"-"&MID(L20,SEARCH("(",L20)+1,SEARCH(")",L20)-SEARCH("(",L20)-1)&"-"&H20&"-"&TEXT(A20,"000")&IF(ISBLANK(N20),"","-"&SUBSTITUTE(N20," ",""))) -> FIC-LIT-বন্-019-Vol1 | D20: নীলকণ্ঠ পাখির খোঁজে | E20: Vol 1 | F20: অতীন বন্দ্যোপাধ্যায় | H20: =IF(ISBLANK(F20),"",IF(G20<>"",UPPER(TRIM(G20)),IF(ISNUMBER(SEARCH(" ",TRIM(F20))),UPPER(LEFT(TRIM(RIGHT(SUBSTITUTE(TRIM(F20)," ",REPT(" ",100)),100)),Settings!$B$9)),UPPER(LEFT(TRIM(F20),Settings!$B$9))))) -> বন্ | K20: Fiction (FIC) | L20: Literature (LIT) | M20: Bengali | N20: Vol 1 | W20: Shelf | X20: B1 | Y20: Good | Z20: =IF(ISBLANK(D20),"",IF(COUNTIFS(Circulation!$B$2:$B$500,A20,Circulation!$H$2:$H$500,"Active")>0,"On Loan","Available")) -> Available
A21: =IF(ISBLANK(D21),"",ROW()-1) -> 20 | B21: ACC-0020 | C21: =IF(ISBLANK(D21),"",MID(K21,SEARCH("(",K21)+1,SEARCH(")",K21)-SEARCH("(",K21)-1)&"-"&MID(L21,SEARCH("(",L21)+1,SEARCH(")",L21)-SEARCH("(",L21)-1)&"-"&H21&"-"&TEXT(A21,"000")&IF(ISBLANK(N21),"","-"&SUBSTITUTE(N21," ",""))) -> #VALUE! | D21: Desh | H21: =IF(ISBLANK(F21),"",IF(G21<>"",UPPER(TRIM(G21)),IF(ISNUMBER(SEARCH(" ",TRIM(F21))),UPPER(LEFT(TRIM(RIGHT(SUBSTITUTE(TRIM(F21)," ",REPT(" ",100)),100)),Settings!$B$9)),UPPER(LEFT(TRIM(F21),Settings!$B$9))))) | K21: Magazine | L21: Literature (LIT) | M21: Bengali | W21: Magazine Rack | X21: MR1 | Y21: Good | Z21: =IF(ISBLANK(D21),"",IF(COUNTIFS(Circulation!$B$2:$B$500,A21,Circulation!$H$2:$H$500,"Active")>0,"On Loan","Available")) -> Available | AG21: Monthly issues
A22: =IF(ISBLANK(D22),"",ROW()-1) | C22: =IF(ISBLANK(D22),"",MID(K22,SEARCH("(",K22)+1,SEARCH(")",K22)-SEARCH("(",K22)-1)&"-"&MID(L22,SEARCH("(",L22)+1,SEARCH(")",L22)-SEARCH("(",L22)-1)&"-"&H22&"-"&TEXT(A22,"000")&IF(ISBLANK(N22),"","-"&SUBSTITUTE(N22," ",""))) | H22: =IF(ISBLANK(F22),"",IF(G22<>"",UPPER(TRIM(G22)),IF(ISNUMBER(SEARCH(" ",TRIM(F22))),UPPER(LEFT(TRIM(RIGHT(SUBSTITUTE(TRIM(F22)," ",REPT(" ",100)),100)),Settings!$B$9)),UPPER(LEFT(TRIM(F22),Settings!$B$9))))) | Z22: =IF(ISBLANK(D22),"",IF(COUNTIFS(Circulation!$B$2:$B$500,A22,Circulation!$H$2:$H$500,"Active")>0,"On Loan","Available"))
A23: =IF(ISBLANK(D23),"",ROW()-1) | C23: =IF(ISBLANK(D23),"",MID(K23,SEARCH("(",K23)+1,SEARCH(")",K23)-SEARCH("(",K23)-1)&"-"&MID(L23,SEARCH("(",L23)+1,SEARCH(")",L23)-SEARCH("(",L23)-1)&"-"&H23&"-"&TEXT(A23,"000")&IF(ISBLANK(N23),"","-"&SUBSTITUTE(N23," ",""))) | H23: =IF(ISBLANK(F23),"",IF(G23<>"",UPPER(TRIM(G23)),IF(ISNUMBER(SEARCH(" ",TRIM(F23))),UPPER(LEFT(TRIM(RIGHT(SUBSTITUTE(TRIM(F23)," ",REPT(" ",100)),100)),Settings!$B$9)),UPPER(LEFT(TRIM(F23),Settings!$B$9))))) | Z23: =IF(ISBLANK(D23),"",IF(COUNTIFS(Circulation!$B$2:$B$500,A23,Circulation!$H$2:$H$500,"Active")>0,"On Loan","Available"))
A24: =IF(ISBLANK(D24),"",ROW()-1) | C24: =IF(ISBLANK(D24),"",MID(K24,SEARCH("(",K24)+1,SEARCH(")",K24)-SEARCH("(",K24)-1)&"-"&MID(L24,SEARCH("(",L24)+1,SEARCH(")",L24)-SEARCH("(",L24)-1)&"-"&H24&"-"&TEXT(A24,"000")&IF(ISBLANK(N24),"","-"&SUBSTITUTE(N24," ",""))) | H24: =IF(ISBLANK(F24),"",IF(G24<>"",UPPER(TRIM(G24)),IF(ISNUMBER(SEARCH(" ",TRIM(F24))),UPPER(LEFT(TRIM(RIGHT(SUBSTITUTE(TRIM(F24)," ",REPT(" ",100)),100)),Settings!$B$9)),UPPER(LEFT(TRIM(F24),Settings!$B$9))))) | Z24: =IF(ISBLANK(D24),"",IF(COUNTIFS(Circulation!$B$2:$B$500,A24,Circulation!$H$2:$H$500,"Active")>0,"On Loan","Available"))
A25: =IF(ISBLANK(D25),"",ROW()-1) | C25: =IF(ISBLANK(D25),"",MID(K25,SEARCH("(",K25)+1,SEARCH(")",K25)-SEARCH("(",K25)-1)&"-"&MID(L25,SEARCH("(",L25)+1,SEARCH(")",L25)-SEARCH("(",L25)-1)&"-"&H25&"-"&TEXT(A25,"000")&IF(ISBLANK(N25),"","-"&SUBSTITUTE(N25," ",""))) | H25: =IF(ISBLANK(F25),"",IF(G25<>"",UPPER(TRIM(G25)),IF(ISNUMBER(SEARCH(" ",TRIM(F25))),UPPER(LEFT(TRIM(RIGHT(SUBSTITUTE(TRIM(F25)," ",REPT(" ",100)),100)),Settings!$B$9)),UPPER(LEFT(TRIM(F25),Settings!$B$9))))) | Z25: =IF(ISBLANK(D25),"",IF(COUNTIFS(Circulation!$B$2:$B$500,A25,Circulation!$H$2:$H$500,"Active")>0,"On Loan","Available"))
A26: =IF(ISBLANK(D26),"",ROW()-1) | C26: =IF(ISBLANK(D26),"",MID(K26,SEARCH("(",K26)+1,SEARCH(")",K26)-SEARCH("(",K26)-1)&"-"&MID(L26,SEARCH("(",L26)+1,SEARCH(")",L26)-SEARCH("(",L26)-1)&"-"&H26&"-"&TEXT(A26,"000")&IF(ISBLANK(N26),"","-"&SUBSTITUTE(N26," ",""))) | H26: =IF(ISBLANK(F26),"",IF(G26<>"",UPPER(TRIM(G26)),IF(ISNUMBER(SEARCH(" ",TRIM(F26))),UPPER(LEFT(TRIM(RIGHT(SUBSTITUTE(TRIM(F26)," ",REPT(" ",100)),100)),Settings!$B$9)),UPPER(LEFT(TRIM(F26),Settings!$B$9))))) | Z26: =IF(ISBLANK(D26),"",IF(COUNTIFS(Circulation!$B$2:$B$500,A26,Circulation!$H$2:$H$500,"Active")>0,"On Loan","Available"))
A27: =IF(ISBLANK(D27),"",ROW()-1) | C27: =IF(ISBLANK(D27),"",MID(K27,SEARCH("(",K27)+1,SEARCH(")",K27)-SEARCH("(",K27)-1)&"-"&MID(L27,SEARCH("(",L27)+1,SEARCH(")",L27)-SEARCH("(",L27)-1)&"-"&H27&"-"&TEXT(A27,"000")&IF(ISBLANK(N27),"","-"&SUBSTITUTE(N27," ",""))) | H27: =IF(ISBLANK(F27),"",IF(G27<>"",UPPER(TRIM(G27)),IF(ISNUMBER(SEARCH(" ",TRIM(F27))),UPPER(LEFT(TRIM(RIGHT(SUBSTITUTE(TRIM(F27)," ",REPT(" ",100)),100)),Settings!$B$9)),UPPER(LEFT(TRIM(F27),Settings!$B$9))))) | Z27: =IF(ISBLANK(D27),"",IF(COUNTIFS(Circulation!$B$2:$B$500,A27,Circulation!$H$2:$H$500,"Active")>0,"On Loan","Available"))
A28: =IF(ISBLANK(D28),"",ROW()-1) | C28: =IF(ISBLANK(D28),"",MID(K28,SEARCH("(",K28)+1,SEARCH(")",K28)-SEARCH("(",K28)-1)&"-"&MID(L28,SEARCH("(",L28)+1,SEARCH(")",L28)-SEARCH("(",L28)-1)&"-"&H28&"-"&TEXT(A28,"000")&IF(ISBLANK(N28),"","-"&SUBSTITUTE(N28," ",""))) | H28: =IF(ISBLANK(F28),"",IF(G28<>"",UPPER(TRIM(G28)),IF(ISNUMBER(SEARCH(" ",TRIM(F28))),UPPER(LEFT(TRIM(RIGHT(SUBSTITUTE(TRIM(F28)," ",REPT(" ",100)),100)),Settings!$B$9)),UPPER(LEFT(TRIM(F28),Settings!$B$9))))) | Z28: =IF(ISBLANK(D28),"",IF(COUNTIFS(Circulation!$B$2:$B$500,A28,Circulation!$H$2:$H$500,"Active")>0,"On Loan","Available"))
A29: =IF(ISBLANK(D29),"",ROW()-1) | C29: =IF(ISBLANK(D29),"",MID(K29,SEARCH("(",K29)+1,SEARCH(")",K29)-SEARCH("(",K29)-1)&"-"&MID(L29,SEARCH("(",L29)+1,SEARCH(")",L29)-SEARCH("(",L29)-1)&"-"&H29&"-"&TEXT(A29,"000")&IF(ISBLANK(N29),"","-"&SUBSTITUTE(N29," ",""))) | H29: =IF(ISBLANK(F29),"",IF(G29<>"",UPPER(TRIM(G29)),IF(ISNUMBER(SEARCH(" ",TRIM(F29))),UPPER(LEFT(TRIM(RIGHT(SUBSTITUTE(TRIM(F29)," ",REPT(" ",100)),100)),Settings!$B$9)),UPPER(LEFT(TRIM(F29),Settings!$B$9))))) | Z29: =IF(ISBLANK(D29),"",IF(COUNTIFS(Circulation!$B$2:$B$500,A29,Circulation!$H$2:$H$500,"Active")>0,"On Loan","Available"))
A30: =IF(ISBLANK(D30),"",ROW()-1) | C30: =IF(ISBLANK(D30),"",MID(K30,SEARCH("(",K30)+1,SEARCH(")",K30)-SEARCH("(",K30)-1)&"-"&MID(L30,SEARCH("(",L30)+1,SEARCH(")",L30)-SEARCH("(",L30)-1)&"-"&H30&"-"&TEXT(A30,"000")&IF(ISBLANK(N30),"","-"&SUBSTITUTE(N30," ",""))) | H30: =IF(ISBLANK(F30),"",IF(G30<>"",UPPER(TRIM(G30)),IF(ISNUMBER(SEARCH(" ",TRIM(F30))),UPPER(LEFT(TRIM(RIGHT(SUBSTITUTE(TRIM(F30)," ",REPT(" ",100)),100)),Settings!$B$9)),UPPER(LEFT(TRIM(F30),Settings!$B$9))))) | Z30: =IF(ISBLANK(D30),"",IF(COUNTIFS(Circulation!$B$2:$B$500,A30,Circulation!$H$2:$H$500,"Active")>0,"On Loan","Available"))
A31: =IF(ISBLANK(D31),"",ROW()-1) | C31: =IF(ISBLANK(D31),"",MID(K31,SEARCH("(",K31)+1,SEARCH(")",K31)-SEARCH("(",K31)-1)&"-"&MID(L31,SEARCH("(",L31)+1,SEARCH(")",L31)-SEARCH("(",L31)-1)&"-"&H31&"-"&TEXT(A31,"000")&IF(ISBLANK(N31),"","-"&SUBSTITUTE(N31," ",""))) | H31: =IF(ISBLANK(F31),"",IF(G31<>"",UPPER(TRIM(G31)),IF(ISNUMBER(SEARCH(" ",TRIM(F31))),UPPER(LEFT(TRIM(RIGHT(SUBSTITUTE(TRIM(F31)," ",REPT(" ",100)),100)),Settings!$B$9)),UPPER(LEFT(TRIM(F31),Settings!$B$9))))) | Z31: =IF(ISBLANK(D31),"",IF(COUNTIFS(Circulation!$B$2:$B$500,A31,Circulation!$H$2:$H$500,"Active")>0,"On Loan","Available"))
A32: =IF(ISBLANK(D32),"",ROW()-1) | C32: =IF(ISBLANK(D32),"",MID(K32,SEARCH("(",K32)+1,SEARCH(")",K32)-SEARCH("(",K32)-1)&"-"&MID(L32,SEARCH("(",L32)+1,SEARCH(")",L32)-SEARCH("(",L32)-1)&"-"&H32&"-"&TEXT(A32,"000")&IF(ISBLANK(N32),"","-"&SUBSTITUTE(N32," ",""))) | H32: =IF(ISBLANK(F32),"",IF(G32<>"",UPPER(TRIM(G32)),IF(ISNUMBER(SEARCH(" ",TRIM(F32))),UPPER(LEFT(TRIM(RIGHT(SUBSTITUTE(TRIM(F32)," ",REPT(" ",100)),100)),Settings!$B$9)),UPPER(LEFT(TRIM(F32),Settings!$B$9))))) | Z32: =IF(ISBLANK(D32),"",IF(COUNTIFS(Circulation!$B$2:$B$500,A32,Circulation!$H$2:$H$500,"Active")>0,"On Loan","Available"))
A33: =IF(ISBLANK(D33),"",ROW()-1) | C33: =IF(ISBLANK(D33),"",MID(K33,SEARCH("(",K33)+1,SEARCH(")",K33)-SEARCH("(",K33)-1)&"-"&MID(L33,SEARCH("(",L33)+1,SEARCH(")",L33)-SEARCH("(",L33)-1)&"-"&H33&"-"&TEXT(A33,"000")&IF(ISBLANK(N33),"","-"&SUBSTITUTE(N33," ",""))) | H33: =IF(ISBLANK(F33),"",IF(G33<>"",UPPER(TRIM(G33)),IF(ISNUMBER(SEARCH(" ",TRIM(F33))),UPPER(LEFT(TRIM(RIGHT(SUBSTITUTE(TRIM(F33)," ",REPT(" ",100)),100)),Settings!$B$9)),UPPER(LEFT(TRIM(F33),Settings!$B$9))))) | Z33: =IF(ISBLANK(D33),"",IF(COUNTIFS(Circulation!$B$2:$B$500,A33,Circulation!$H$2:$H$500,"Active")>0,"On Loan","Available"))
... A501: =IF(ISBLANK(D501),"",ROW()-1) | C501: =IF(ISBLANK(D501),"",MID(K501,SEARCH("(",K501)+1,SEARCH(")",K501)-SEARCH("(",K501)-1)&"-"&MID(L501,SEARCH("(",L501)+1,SEARCH(")",L501)-SEARCH("(",L501)-1)&"-"&H501&"-"&TEXT(A501,"000")&IF(ISBLANK(N501),"","-"&SUBSTITUTE(N501," ",""))) | H501: =IF(ISBLANK(F501),"",IF(G501<>"",UPPER(TRIM(G501)),IF(ISNUMBER(SEARCH(" ",TRIM(F501))),UPPER(LEFT(TRIM(RIGHT(SUBSTITUTE(TRIM(F501)," ",REPT(" ",100)),100)),Settings!$B$9)),UPPER(LEFT(TRIM(F501),Settings!$B$9))))) | Z501: =IF(ISBLANK(D501),"",IF(COUNTIFS(Circulation!$B$2:$B$500,A501,Circulation!$H$2:$H$500,"Active")>0,"On Loan","Available"))

Sheet Digital_Catalog
A1: Resource ID | B1: Digital Call Number | C1: Title | D1: Creator | E1: Contributor | F1: Resource Type | G1: Genre | H1: Language | I1: Format | J1: MIME Type | K1: File Extension | L1: File Size (bytes) | M1: Storage Path | N1: URI | O1: OCR Status | P1: Searchable | Q1: Date Created | R1: Date Added | S1: Rights | T1: Access Level | U1: Description | V1: Related Physical ID | W1: Related Work ID | X1: Archive ID | Y1: Checksum | Z1: Reading/Usage Status | AA1: Preservation Status
A2: =IF(ISBLANK(C2),"",ROW()-1) -> 1 | B2: =IF(ISBLANK(C2),"","DIG-"&MID(F2,SEARCH("(",F2)+1,3)&"-"&MID(G2,SEARCH("(",G2)+1,3)&"-"&UPPER(LEFT(TRIM(RIGHT(SUBSTITUTE(TRIM(D2)," ",REPT(" ",100)),100)),3))&"-"&TEXT(A2,"000")) -> #VALUE! | C2: The Pocket Oracle | D2: Baltasar Gracian | F2: Book | G2: Philosophy (PHI) | H2: English | I2: PDF | J2: application/pdf | K2: .pdf | M2: Drive/Books/Philosophy | O2: Searchable (OCR) | P2: Yes | Q2: 2024-01-15 | S2: Copyright | T2: Private | U2: A pocket edition of Gracian's aphorisms. | Z2: Unread | AA2: Master
A3: =IF(ISBLANK(C3),"",ROW()-1) -> 2 | B3: =IF(ISBLANK(C3),"","DIG-"&MID(F3,SEARCH("(",F3)+1,3)&"-"&MID(G3,SEARCH("(",G3)+1,3)&"-"&UPPER(LEFT(TRIM(RIGHT(SUBSTITUTE(TRIM(D3)," ",REPT(" ",100)),100)),3))&"-"&TEXT(A3,"000")) -> #VALUE! | C3: নীলকণ্ঠ পাখির খোঁজে | D3: অতীন বন্দ্যোপাধ্যায় | F3: Book | G3: Literature (LIT) | H3: Bengali | I3: PDF | J3: application/pdf | K3: .pdf | M3: Drive/Books/Bengali_Classics | O3: Scanned (No OCR) | P3: No | Q3: 2023-06-01 | S3: Copyright | T3: Private | U3: Scanned copy of Bengali novel. | Z3: Unread | AA3: Master
A4: =IF(ISBLANK(C4),"",ROW()-1) -> 3 | B4: =IF(ISBLANK(C4),"","DIG-"&MID(F4,SEARCH("(",F4)+1,3)&"-"&MID(G4,SEARCH("(",G4)+1,3)&"-"&UPPER(LEFT(TRIM(RIGHT(SUBSTITUTE(TRIM(D4)," ",REPT(" ",100)),100)),3))&"-"&TEXT(A4,"000")) -> #VALUE! | C4: The Great Derangement | D4: Amitav Ghosh | F4: Book | G4: Essays (ESS) | H4: English | I4: EPUB | J4: application/epub+zip | K4: .epub | M4: Drive/Books/Essays | O4: Searchable (OCR) | P4: Yes | Q4: 2023-02-10 | S4: Copyright | T4: Private | U4: Climate change essays. | Z4: Read | AA4: Master
A5: =IF(ISBLANK(C5),"",ROW()-1) -> 4 | B5: =IF(ISBLANK(C5),"","DIG-"&MID(F5,SEARCH("(",F5)+1,3)&"-"&MID(G5,SEARCH("(",G5)+1,3)&"-"&UPPER(LEFT(TRIM(RIGHT(SUBSTITUTE(TRIM(D5)," ",REPT(" ",100)),100)),3))&"-"&TEXT(A5,"000")) -> #VALUE! | C5: Bengali literary reading | F5: Audio Recording | G5: Literature (LIT) | H5: Bengali | I5: FLAC | J5: audio/flac | K5: .flac | M5: Drive/Archive/Audio | O5: Not Applicable | P5: No | Q5: 2023-08-12 | S5: User-Owned | T5: Private | U5: Live reading of Tagore poems. | Z5: N/A | AA5: Master
A6: =IF(ISBLANK(C6),"",ROW()-1) -> 5 | B6: =IF(ISBLANK(C6),"","DIG-"&MID(F6,SEARCH("(",F6)+1,3)&"-"&MID(G6,SEARCH("(",G6)+1,3)&"-"&UPPER(LEFT(TRIM(RIGHT(SUBSTITUTE(TRIM(D6)," ",REPT(" ",100)),100)),3))&"-"&TEXT(A6,"000")) -> #VALUE! | C6: Interview with an author | F6: Video Recording | G6: Literature (LIT) | H6: Bengali | I6: MP4 | J6: video/mp4 | K6: .mp4 | M6: Drive/Archive/Video | O6: Not Applicable | P6: No | Q6: 2024-03-01 | S6: User-Owned | T6: Restricted | U6: Recorded interview. | Z6: N/A | AA6: Master
A7: =IF(ISBLANK(C7),"",ROW()-1) -> 6 | B7: =IF(ISBLANK(C7),"","DIG-"&MID(F7,SEARCH("(",F7)+1,3)&"-"&MID(G7,SEARCH("(",G7)+1,3)&"-"&UPPER(LEFT(TRIM(RIGHT(SUBSTITUTE(TRIM(D7)," ",REPT(" ",100)),100)),3))&"-"&TEXT(A7,"000")) -> #VALUE! | C7: Scanned Bengali manuscript | F7: Manuscript | G7: Literature (LIT) | H7: Bengali | I7: TIFF | J7: image/tiff | K7: .tiff | M7: Archive/Manuscripts | O7: Scanned (No OCR) | P7: No | Q7: 2022-01-01 | S7: Public Domain | T7: Research Only | U7: High-res scan of 19th-c manuscript. | X7: ARC-0001 | Z7: N/A | AA7: Master
A8: =IF(ISBLANK(C8),"",ROW()-1) | B8: =IF(ISBLANK(C8),"","DIG-"&MID(F8,SEARCH("(",F8)+1,3)&"-"&MID(G8,SEARCH("(",G8)+1,3)&"-"&UPPER(LEFT(TRIM(RIGHT(SUBSTITUTE(TRIM(D8)," ",REPT(" ",100)),100)),3))&"-"&TEXT(A8,"000"))
A9: =IF(ISBLANK(C9),"",ROW()-1) | B9: =IF(ISBLANK(C9),"","DIG-"&MID(F9,SEARCH("(",F9)+1,3)&"-"&MID(G9,SEARCH("(",G9)+1,3)&"-"&UPPER(LEFT(TRIM(RIGHT(SUBSTITUTE(TRIM(D9)," ",REPT(" ",100)),100)),3))&"-"&TEXT(A9,"000"))
A10: =IF(ISBLANK(C10),"",ROW()-1) | B10: =IF(ISBLANK(C10),"","DIG-"&MID(F10,SEARCH("(",F10)+1,3)&"-"&MID(G10,SEARCH("(",G10)+1,3)&"-"&UPPER(LEFT(TRIM(RIGHT(SUBSTITUTE(TRIM(D10)," ",REPT(" ",100)),100)),3))&"-"&TEXT(A10,"000"))
A11: =IF(ISBLANK(C11),"",ROW()-1) | B11: =IF(ISBLANK(C11),"","DIG-"&MID(F11,SEARCH("(",F11)+1,3)&"-"&MID(G11,SEARCH("(",G11)+1,3)&"-"&UPPER(LEFT(TRIM(RIGHT(SUBSTITUTE(TRIM(D11)," ",REPT(" ",100)),100)),3))&"-"&TEXT(A11,"000"))
A12: =IF(ISBLANK(C12),"",ROW()-1) | B12: =IF(ISBLANK(C12),"","DIG-"&MID(F12,SEARCH("(",F12)+1,3)&"-"&MID(G12,SEARCH("(",G12)+1,3)&"-"&UPPER(LEFT(TRIM(RIGHT(SUBSTITUTE(TRIM(D12)," ",REPT(" ",100)),100)),3))&"-"&TEXT(A12,"000"))
A13: =IF(ISBLANK(C13),"",ROW()-1) | B13: =IF(ISBLANK(C13),"","DIG-"&MID(F13,SEARCH("(",F13)+1,3)&"-"&MID(G13,SEARCH("(",G13)+1,3)&"-"&UPPER(LEFT(TRIM(RIGHT(SUBSTITUTE(TRIM(D13)," ",REPT(" ",100)),100)),3))&"-"&TEXT(A13,"000"))
A14: =IF(ISBLANK(C14),"",ROW()-1) | B14: =IF(ISBLANK(C14),"","DIG-"&MID(F14,SEARCH("(",F14)+1,3)&"-"&MID(G14,SEARCH("(",G14)+1,3)&"-"&UPPER(LEFT(TRIM(RIGHT(SUBSTITUTE(TRIM(D14)," ",REPT(" ",100)),100)),3))&"-"&TEXT(A14,"000"))
A15: =IF(ISBLANK(C15),"",ROW()-1) | B15: =IF(ISBLANK(C15),"","DIG-"&MID(F15,SEARCH("(",F15)+1,3)&"-"&MID(G15,SEARCH("(",G15)+1,3)&"-"&UPPER(LEFT(TRIM(RIGHT(SUBSTITUTE(TRIM(D15)," ",REPT(" ",100)),100)),3))&"-"&TEXT(A15,"000"))
A16: =IF(ISBLANK(C16),"",ROW()-1) | B16: =IF(ISBLANK(C16),"","DIG-"&MID(F16,SEARCH("(",F16)+1,3)&"-"&MID(G16,SEARCH("(",G16)+1,3)&"-"&UPPER(LEFT(TRIM(RIGHT(SUBSTITUTE(TRIM(D16)," ",REPT(" ",100)),100)),3))&"-"&TEXT(A16,"000"))
A17: =IF(ISBLANK(C17),"",ROW()-1) | B17: =IF(ISBLANK(C17),"","DIG-"&MID(F17,SEARCH("(",F17)+1,3)&"-"&MID(G17,SEARCH("(",G17)+1,3)&"-"&UPPER(LEFT(TRIM(RIGHT(SUBSTITUTE(TRIM(D17)," ",REPT(" ",100)),100)),3))&"-"&TEXT(A17,"000"))
A18: =IF(ISBLANK(C18),"",ROW()-1) | B18: =IF(ISBLANK(C18),"","DIG-"&MID(F18,SEARCH("(",F18)+1,3)&"-"&MID(G18,SEARCH("(",G18)+1,3)&"-"&UPPER(LEFT(TRIM(RIGHT(SUBSTITUTE(TRIM(D18)," ",REPT(" ",100)),100)),3))&"-"&TEXT(A18,"000"))
A19: =IF(ISBLANK(C19),"",ROW()-1) | B19: =IF(ISBLANK(C19),"","DIG-"&MID(F19,SEARCH("(",F19)+1,3)&"-"&MID(G19,SEARCH("(",G19)+1,3)&"-"&UPPER(LEFT(TRIM(RIGHT(SUBSTITUTE(TRIM(D19)," ",REPT(" ",100)),100)),3))&"-"&TEXT(A19,"000"))
... A501: =IF(ISBLANK(C501),"",ROW()-1) | B501: =IF(ISBLANK(C501),"","DIG-"&MID(F501,SEARCH("(",F501)+1,3)&"-"&MID(G501,SEARCH("(",G501)+1,3)&"-"&UPPER(LEFT(TRIM(RIGHT(SUBSTITUTE(TRIM(D501)," ",REPT(" ",100)),100)),3))&"-"&TEXT(A501,"000"))

Sheet Archive
A1: Archive ID | B1: Title | C1: Creator | D1: Date | E1: Description | F1: Resource Type | G1: Physical/Digital | H1: Language | I1: Provenance | J1: Acquisition | K1: Condition | L1: Location Type | M1: Location Identifier | N1: Digital Surrogate | O1: Digitisation Status | P1: OCR Status | Q1: Rights | R1: Access Level | S1: Related Resource ID | T1: Notes
A2: =IF(ISBLANK(B2),"","ARC-"&TEXT(ROW()-1,"0000")) -> ARC-0001 | B2: Historical newspaper clipping | D2: 1947-08-15 | E2: Bengali newspaper clipping from independence era. | F2: Newspaper Clipping | G2: Physical | H2: Bengali | I2: Family collection | J2: Inherited | K2: Fair | L2: Archive | M2: ARCH-01 | O2: Not Digitised | P2: Not Applicable | Q2: Unknown | R2: Private | T2: Fragile; store in acid-free sleeve.
A3: =IF(ISBLANK(B3),"","ARC-"&TEXT(ROW()-1,"0000")) -> ARC-0002 | B3: Scanned Bengali manuscript | D3: 1890 | E3: Digitised manuscript. | F3: Manuscript | G3: Digital | H3: Bengali | I3: Purchased at auction | J3: Purchase | K3: Good | L3: Archive | M3: ARCH-02 | O3: Scanned | P3: OCR Pending | Q3: Public Domain | R3: Research Only | T3: High-res TIFF master.
A4: =IF(ISBLANK(B4),"","ARC-"&TEXT(ROW()-1,"0000"))
A5: =IF(ISBLANK(B5),"","ARC-"&TEXT(ROW()-1,"0000"))
A6: =IF(ISBLANK(B6),"","ARC-"&TEXT(ROW()-1,"0000"))
A7: =IF(ISBLANK(B7),"","ARC-"&TEXT(ROW()-1,"0000"))
A8: =IF(ISBLANK(B8),"","ARC-"&TEXT(ROW()-1,"0000"))
A9: =IF(ISBLANK(B9),"","ARC-"&TEXT(ROW()-1,"0000"))
A10: =IF(ISBLANK(B10),"","ARC-"&TEXT(ROW()-1,"0000"))
A11: =IF(ISBLANK(B11),"","ARC-"&TEXT(ROW()-1,"0000"))
A12: =IF(ISBLANK(B12),"","ARC-"&TEXT(ROW()-1,"0000"))
A13: =IF(ISBLANK(B13),"","ARC-"&TEXT(ROW()-1,"0000"))
A14: =IF(ISBLANK(B14),"","ARC-"&TEXT(ROW()-1,"0000"))
A15: =IF(ISBLANK(B15),"","ARC-"&TEXT(ROW()-1,"0000"))
... A201: =IF(ISBLANK(B201),"","ARC-"&TEXT(ROW()-1,"0000"))

Sheet Circulation
A1: Loan ID | B1: Item ID | C1: Member ID | D1: Borrower Name | E1: Checkout Date | F1: Due Date | G1: Return Date | H1: Status | I1: Notes
A2: =IF(ISBLANK(B2),"",ROW()-1) | D2: =IFERROR(IF(ISBLANK(C2),"",VLOOKUP(C2,Members!$A$2:$B$101,2,FALSE)),"") | F2: =IF(ISBLANK(E2),"",E2+Settings!$B$7) | H2: =IF(ISBLANK(B2),"",IF(NOT(ISBLANK(G2)),"Returned",IF(TODAY()>F2,"Overdue","Active")))
A3: =IF(ISBLANK(B3),"",ROW()-1) | D3: =IFERROR(IF(ISBLANK(C3),"",VLOOKUP(C3,Members!$A$2:$B$101,2,FALSE)),"") | F3: =IF(ISBLANK(E3),"",E3+Settings!$B$7) | H3: =IF(ISBLANK(B3),"",IF(NOT(ISBLANK(G3)),"Returned",IF(TODAY()>F3,"Overdue","Active")))
A4: =IF(ISBLANK(B4),"",ROW()-1) | D4: =IFERROR(IF(ISBLANK(C4),"",VLOOKUP(C4,Members!$A$2:$B$101,2,FALSE)),"") | F4: =IF(ISBLANK(E4),"",E4+Settings!$B$7) | H4: =IF(ISBLANK(B4),"",IF(NOT(ISBLANK(G4)),"Returned",IF(TODAY()>F4,"Overdue","Active")))
A5: =IF(ISBLANK(B5),"",ROW()-1) | D5: =IFERROR(IF(ISBLANK(C5),"",VLOOKUP(C5,Members!$A$2:$B$101,2,FALSE)),"") | F5: =IF(ISBLANK(E5),"",E5+Settings!$B$7) | H5: =IF(ISBLANK(B5),"",IF(NOT(ISBLANK(G5)),"Returned",IF(TODAY()>F5,"Overdue","Active")))
A6: =IF(ISBLANK(B6),"",ROW()-1) | D6: =IFERROR(IF(ISBLANK(C6),"",VLOOKUP(C6,Members!$A$2:$B$101,2,FALSE)),"") | F6: =IF(ISBLANK(E6),"",E6+Settings!$B$7) | H6: =IF(ISBLANK(B6),"",IF(NOT(ISBLANK(G6)),"Returned",IF(TODAY()>F6,"Overdue","Active")))
A7: =IF(ISBLANK(B7),"",ROW()-1) | D7: =IFERROR(IF(ISBLANK(C7),"",VLOOKUP(C7,Members!$A$2:$B$101,2,FALSE)),"") | F7: =IF(ISBLANK(E7),"",E7+Settings!$B$7) | H7: =IF(ISBLANK(B7),"",IF(NOT(ISBLANK(G7)),"Returned",IF(TODAY()>F7,"Overdue","Active")))
A8: =IF(ISBLANK(B8),"",ROW()-1) | D8: =IFERROR(IF(ISBLANK(C8),"",VLOOKUP(C8,Members!$A$2:$B$101,2,FALSE)),"") | F8: =IF(ISBLANK(E8),"",E8+Settings!$B$7) | H8: =IF(ISBLANK(B8),"",IF(NOT(ISBLANK(G8)),"Returned",IF(TODAY()>F8,"Overdue","Active")))
A9: =IF(ISBLANK(B9),"",ROW()-1) | D9: =IFERROR(IF(ISBLANK(C9),"",VLOOKUP(C9,Members!$A$2:$B$101,2,FALSE)),"") | F9: =IF(ISBLANK(E9),"",E9+Settings!$B$7) | H9: =IF(ISBLANK(B9),"",IF(NOT(ISBLANK(G9)),"Returned",IF(TODAY()>F9,"Overdue","Active")))
A10: =IF(ISBLANK(B10),"",ROW()-1) | D10: =IFERROR(IF(ISBLANK(C10),"",VLOOKUP(C10,Members!$A$2:$B$101,2,FALSE)),"") | F10: =IF(ISBLANK(E10),"",E10+Settings!$B$7) | H10: =IF(ISBLANK(B10),"",IF(NOT(ISBLANK(G10)),"Returned",IF(TODAY()>F10,"Overdue","Active")))
A11: =IF(ISBLANK(B11),"",ROW()-1) | D11: =IFERROR(IF(ISBLANK(C11),"",VLOOKUP(C11,Members!$A$2:$B$101,2,FALSE)),"") | F11: =IF(ISBLANK(E11),"",E11+Settings!$B$7) | H11: =IF(ISBLANK(B11),"",IF(NOT(ISBLANK(G11)),"Returned",IF(TODAY()>F11,"Overdue","Active")))
A12: =IF(ISBLANK(B12),"",ROW()-1) | D12: =IFERROR(IF(ISBLANK(C12),"",VLOOKUP(C12,Members!$A$2:$B$101,2,FALSE)),"") | F12: =IF(ISBLANK(E12),"",E12+Settings!$B$7) | H12: =IF(ISBLANK(B12),"",IF(NOT(ISBLANK(G12)),"Returned",IF(TODAY()>F12,"Overdue","Active")))
A13: =IF(ISBLANK(B13),"",ROW()-1) | D13: =IFERROR(IF(ISBLANK(C13),"",VLOOKUP(C13,Members!$A$2:$B$101,2,FALSE)),"") | F13: =IF(ISBLANK(E13),"",E13+Settings!$B$7) | H13: =IF(ISBLANK(B13),"",IF(NOT(ISBLANK(G13)),"Returned",IF(TODAY()>F13,"Overdue","Active")))
... A501: =IF(ISBLANK(B501),"",ROW()-1) | D501: =IFERROR(IF(ISBLANK(C501),"",VLOOKUP(C501,Members!$A$2:$B$101,2,FALSE)),"") | F501: =IF(ISBLANK(E501),"",E501+Settings!$B$7) | H501: =IF(ISBLANK(B501),"",IF(NOT(ISBLANK(G501)),"Returned",IF(TODAY()>F501,"Overdue","Active")))

Sheet Members
A1: Member ID | B1: Name | C1: Contact | D1: Membership Type | E1: Join Date | F1: Status | G1: Notes
A2: M001 | B2: Sample Borrower | D2: Public | E2: 2024-01-01 | F2: Active

Sheet Spine_Labels
A1: Item ID | B1: Call Number | C1: Title | D1: Volume/Issue | E1: Creator | F1: Location | G1: Label Type
A2: =Catalog!A2 -> 1 | B2: =Catalog!C2 -> FIC-LIT-TAG-001-Vol1 | C2: =Catalog!D2 -> Rabindra Rachanabali | D2: =Catalog!N2 -> Vol 1 | E2: =Catalog!F2 -> Rabindranath Tagore | F2: =IF(Catalog!W2="","",Catalog!W2&" "&Catalog!X2) -> Shelf A2
A3: =Catalog!A3 -> 2 | B3: =Catalog!C3 -> FIC-LIT-TAG-002-Vol2 | C3: =Catalog!D3 -> Rabindra Rachanabali | D3: =Catalog!N3 -> Vol 2 | E3: =Catalog!F3 -> Rabindranath Tagore | F3: =IF(Catalog!W3="","",Catalog!W3&" "&Catalog!X3) -> Shelf A2
A4: =Catalog!A4 -> 3 | B4: =Catalog!C4 -> FIC-LIT-TAG-003-Vol3 | C4: =Catalog!D4 -> Rabindra Rachanabali | D4: =Catalog!N4 -> Vol 3 | E4: =Catalog!F4 -> Rabindranath Tagore | F4: =IF(Catalog!W4="","",Catalog!W4&" "&Catalog!X4) -> Shelf A2
A5: =Catalog!A5 -> 4 | B5: =Catalog!C5 -> FIC-LIT-TAG-004-Vol4 | C5: =Catalog!D5 -> Rabindra Rachanabali | D5: =Catalog!N5 -> Vol 4 | E5: =Catalog!F5 -> Rabindranath Tagore | F5: =IF(Catalog!W5="","",Catalog!W5&" "&Catalog!X5) -> Shelf A2
A6: =Catalog!A6 -> 5 | B6: =Catalog!C6 -> FIC-LIT-TAG-005-Vol5 | C6: =Catalog!D6 -> Rabindra Rachanabali | D6: =Catalog!N6 -> Vol 5 | E6: =Catalog!F6 -> Rabindranath Tagore | F6: =IF(Catalog!W6="","",Catalog!W6&" "&Catalog!X6) -> Shelf A2
A7: =Catalog!A7 -> 6 | B7: =Catalog!C7 -> FIC-LIT-TAG-006-Vol6 | C7: =Catalog!D7 -> Rabindra Rachanabali | D7: =Catalog!N7 -> Vol 6 | E7: =Catalog!F7 -> Rabindranath Tagore | F7: =IF(Catalog!W7="","",Catalog!W7&" "&Catalog!X7) -> Shelf A2
A8: =Catalog!A8 -> 7 | B8: =Catalog!C8 -> FIC-LIT-TAG-007-Vol7 | C8: =Catalog!D8 -> Rabindra Rachanabali | D8: =Catalog!N8 -> Vol 7 | E8: =Catalog!F8 -> Rabindranath Tagore | F8: =IF(Catalog!W8="","",Catalog!W8&" "&Catalog!X8) -> Shelf A2
A9: =Catalog!A9 -> 8 | B9: =Catalog!C9 -> FIC-LIT-TAG-008-Vol8 | C9: =Catalog!D9 -> Rabindra Rachanabali | D9: =Catalog!N9 -> Vol 8 | E9: =Catalog!F9 -> Rabindranath Tagore | F9: =IF(Catalog!W9="","",Catalog!W9&" "&Catalog!X9) -> Shelf A2
A10: =Catalog!A10 -> 9 | B10: =Catalog!C10 -> FIC-LIT-TAG-009-Vol9 | C10: =Catalog!D10 -> Rabindra Rachanabali | D10: =Catalog!N10 -> Vol 9 | E10: =Catalog!F10 -> Rabindranath Tagore | F10: =IF(Catalog!W10="","",Catalog!W10&" "&Catalog!X10) -> Shelf A1
A11: =Catalog!A11 -> 10 | B11: =Catalog!C11 -> FIC-LIT-TAG-010-Vol10 | C11: =Catalog!D11 -> Rabindra Rachanabali | D11: =Catalog!N11 -> Vol 10 | E11: =Catalog!F11 -> Rabindranath Tagore | F11: =IF(Catalog!W11="","",Catalog!W11&" "&Catalog!X11) -> Shelf A1
A12: =Catalog!A12 -> 11 | B12: =Catalog!C12 -> FIC-LIT-TAG-011-Vol11 | C12: =Catalog!D12 -> Rabindra Rachanabali | D12: =Catalog!N12 -> Vol 11 | E12: =Catalog!F12 -> Rabindranath Tagore | F12: =IF(Catalog!W12="","",Catalog!W12&" "&Catalog!X12) -> Shelf A1
A13: =Catalog!A13 -> 12 | B13: =Catalog!C13 -> FIC-LIT-TAG-012-Vol12 | C13: =Catalog!D13 -> Rabindra Rachanabali | D13: =Catalog!N13 -> Vol 12 | E13: =Catalog!F13 -> Rabindranath Tagore | F13: =IF(Catalog!W13="","",Catalog!W13&" "&Catalog!X13) -> Shelf A1
... A501: =Catalog!A501 | B501: =Catalog!C501 | C501: =Catalog!D501 -> 0 | D501: =Catalog!N501 -> 0 | E501: =Catalog!F501 -> 0 | F501: =IF(Catalog!W501="","",Catalog!W501&" "&Catalog!X501)

Sheet Settings
A1: SETTINGS — Personal Library Manager
A3: Setting | B3: Value | C3: Purpose
A4: Library Name | B4: Personal Library | C4: Display name of the library
A5: Collection Name | B5: Main Collection | C5: Name of the primary collection
A6: Default Language | B6: English | C6: Default language for new records
A7: Default Loan Period (days) | B7: 14 | C7: Circulation loan period in days
A8: Accession Prefix | B8: ACC | C8: Prefix for accession numbers
A9: Author Code Length | B9: 3 | C9: Number of letters for auto author code
A10: Date Format | B10: YYYY-MM-DD | C10: Display format for dates
A11: Default Resource Type | B11: Book | C11: Default resource type
A12: Metadata Profile Version | B12: 2.0 | C12: Dublin Core profile version
A13: Workbook Protection Password | B13: library | C13: Password to unprotect sheets

Sheet Lookup_Codes
A1: Resource Type | B1: Genre | C1: Language | D1: Format | E1: OCR Status | F1: Condition | G1: Circulation Status | H1: Location Type | I1: Access Level | J1: Rights | K1: Acquisition Type | L1: Frequency | M1: Digitisation Status | N1: Physical/Digital | O1: Membership Type | P1: Member Status | Q1: Reading/Usage Status | R1: Preservation Status
A2: Book | B2: Literature (LIT) | C2: English | D2: PDF | E2: Not Applicable | F2: New | G2: Available | H2: Shelf | I2: Public | J2: Copyright | K2: Purchase | L2: Daily | M2: Not Digitised | N2: Physical | O2: Student | P2: Active | Q2: Read | R2: Master
A3: Magazine | B3: History (HIS) | C3: Bengali | D3: EPUB | E3: Not Digitised | F3: Excellent | G3: On Loan | H3: Magazine Rack | I3: Private | J3: Public Domain | K3: Gift | L3: Weekly | M3: Digitisation Planned | N3: Digital | O3: Faculty | P3: Inactive | Q3: Reading | R3: Derivative
A4: Journal | B4: Philosophy (PHI) | C4: Hindi | D4: MOBI | E4: Scanned (No OCR) | F4: Good | G4: Reference Only | H4: Journal Rack | I4: Restricted | J4: Licensed | K4: Donation | L4: Fortnightly | M4: Scanned | N4: Both | O4: Public | P4: Suspended | Q4: Unread | R4: Archived
A5: Periodical | B5: Science & Tech (SCI) | C5: Other | D5: DJVU | E5: OCR Pending | F5: Fair | G5: Lost | H5: Archive | I5: Research Only | J5: Unknown | K5: Exchange | L5: Monthly | M5: OCR Pending | O5: Institutional | Q5: N/A | R5: At Risk
A6: Newsletter | B6: Politics (POL) | D6: TXT | E6: OCR Complete | F6: Poor | G6: Withdrawn | H6: Cabinet | I6: Permission Required | J6: User-Owned | K6: Legacy | L6: Bi-Monthly | M6: OCR Complete | O6: Other
A7: Annual | B7: Essays (ESS) | D7: DOCX | E7: Searchable (OCR) | F7: Damaged | H7: Box | J7: Institutional | K7: Unknown | L7: Quarterly | M7: OCR Verified
A8: Special Issue | B8: Biography / Memoir (BIO) | D8: HTML | E8: Image Only | F8: Under Repair | H8: Other | J8: Other | L8: Annual
A9: Article | B9: Mystery / Thriller (THR) | D9: XML | L9: Irregular
A10: Image | B10: Religion & Mythology (REL) | D10: TEI XML
A11: Audio Recording | B11: Art & Cinema (ART) | D11: Markdown
A12: Video Recording | B12: Other | D12: RTF
A13: Dataset | D13: JPG
A14: Website | D14: JPEG
A15: Manuscript | D15: PNG
A16: Newspaper | D16: TIFF
A17: Newspaper Clipping | D17: WebP
A18: Photograph | D18: MP3
A19: Poster | D19: WAV
A20: Map | D20: FLAC
A21: Pamphlet | D21: M4A
A22: Brochure | D22: MP4
A23: Personal Papers | D23: MKV
A24: Ephemera | D24: MOV
A25: Other | D25: WebM
D26: ZIP
D27: Other

Sheet Dublin_Core
A1: DUBLIN CORE METADATA MAPPING
A3: Dublin Core Element | B3: Catalog Field | C3: Notes
A4: title | B4: Title | C4: Standard DC element
A5: creator | B5: Creator | C5: Standard DC element
A6: contributor | B6: Editor, Translator | C6: Standard DC element; application-specific split
A7: publisher | B7: Publisher | C7: Standard DC element
A8: date | B8: Publication Year | C8: Standard DC element
A9: language | B9: Language | C9: Standard DC element
A10: type | B10: Type | C10: Standard DC element; project vocabulary
A11: format | B11: Format, Pages | C11: Standard DC element
A12: identifier | B12: ISBN, ISSN, Accession Number, Call Number | C12: Standard DC element
A13: subject | B13: Genre | C13: Standard DC element
A14: description | B14: Notes, Description | C14: Standard DC element
... A21: — | B21: Digital storage path, OCR status, Checksum | C21: Application-specific extension (not DC)
A25: EXPORT VIEW — Dublin Core element columns
A27: dc.title | B27: dc.creator | C27: dc.contributor | D27: dc.publisher | E27: dc.date | F27: dc.language | G27: dc.type | H27: dc.format | I27: dc.identifier | J27: dc.subject | K27: dc.description | L27: dc.source | M27: dc.relation | N27: dc.coverage | O27: dc.rights
A28: =Catalog!D2 -> Rabindra Rachanabali | B28: =Catalog!F2 -> Rabindranath Tagore | C28: =IF(Catalog!I2="","",Catalog!I2)&IF(AND(Catalog!I2<>"",Catalog!J2<>""),"; ","")&IF(Catalog!J2="","",Catalog!J2) | D28: =Catalog!P2 -> 0 | E28: =Catalog!R2 -> 0 | F28: =Catalog!M2 -> Bengali | G28: =Catalog!K2 -> Fiction (FIC) | H28: =IF(Catalog!S2<>"","ISBN:"&Catalog!S2,IF(Catalog!T2<>"","ISSN:"&Catalog!T2,"")) | I28: =Catalog!B2 -> ACC-0001 | J28: =Catalog!L2 -> Literature (LIT) | K28: =IF(Catalog!AG2<>"",Catalog!AG2,Catalog!AE2) -> 0 | L28: =Catalog!AD2 -> 0 | M28: =Catalog!V2 -> 0 | N28: =Catalog!Q2 -> 0 | O28: =Catalog!AF2 -> 0
A29: =Catalog!D3 -> Rabindra Rachanabali | B29: =Catalog!F3 -> Rabindranath Tagore | C29: =IF(Catalog!I3="","",Catalog!I3)&IF(AND(Catalog!I3<>"",Catalog!J3<>""),"; ","")&IF(Catalog!J3="","",Catalog!J3) | D29: =Catalog!P3 -> 0 | E29: =Catalog!R3 -> 0 | F29: =Catalog!M3 -> Bengali | G29: =Catalog!K3 -> Fiction (FIC) | H29: =IF(Catalog!S3<>"","ISBN:"&Catalog!S3,IF(Catalog!T3<>"","ISSN:"&Catalog!T3,"")) | I29: =Catalog!B3 -> ACC-0002 | J29: =Catalog!L3 -> Literature (LIT) | K29: =IF(Catalog!AG3<>"",Catalog!AG3,Catalog!AE3) -> 0 | L29: =Catalog!AD3 -> 0 | M29: =Catalog!V3 -> 0 | N29: =Catalog!Q3 -> 0 | O29: =Catalog!AF3 -> 0
A30: =Catalog!D4 -> Rabindra Rachanabali | B30: =Catalog!F4 -> Rabindranath Tagore | C30: =IF(Catalog!I4="","",Catalog!I4)&IF(AND(Catalog!I4<>"",Catalog!J4<>""),"; ","")&IF(Catalog!J4="","",Catalog!J4) | D30: =Catalog!P4 -> 0 | E30: =Catalog!R4 -> 0 | F30: =Catalog!M4 -> Bengali | G30: =Catalog!K4 -> Fiction (FIC) | H30: =IF(Catalog!S4<>"","ISBN:"&Catalog!S4,IF(Catalog!T4<>"","ISSN:"&Catalog!T4,"")) | I30: =Catalog!B4 -> ACC-0003 | J30: =Catalog!L4 -> Literature (LIT) | K30: =IF(Catalog!AG4<>"",Catalog!AG4,Catalog!AE4) -> 0 | L30: =Catalog!AD4 -> 0 | M30: =Catalog!V4 -> 0 | N30: =Catalog!Q4 -> 0 | O30: =Catalog!AF4 -> 0
A31: =Catalog!D5 -> Rabindra Rachanabali | B31: =Catalog!F5 -> Rabindranath Tagore | C31: =IF(Catalog!I5="","",Catalog!I5)&IF(AND(Catalog!I5<>"",Catalog!J5<>""),"; ","")&IF(Catalog!J5="","",Catalog!J5) | D31: =Catalog!P5 -> 0 | E31: =Catalog!R5 -> 0 | F31: =Catalog!M5 -> Bengali | G31: =Catalog!K5 -> Fiction (FIC) | H31: =IF(Catalog!S5<>"","ISBN:"&Catalog!S5,IF(Catalog!T5<>"","ISSN:"&Catalog!T5,"")) | I31: =Catalog!B5 -> ACC-0004 | J31: =Catalog!L5 -> Literature (LIT) | K31: =IF(Catalog!AG5<>"",Catalog!AG5,Catalog!AE5) -> 0 | L31: =Catalog!AD5 -> 0 | M31: =Catalog!V5 -> 0 | N31: =Catalog!Q5 -> 0 | O31: =Catalog!AF5 -> 0
A32: =Catalog!D6 -> Rabindra Rachanabali | B32: =Catalog!F6 -> Rabindranath Tagore | C32: =IF(Catalog!I6="","",Catalog!I6)&IF(AND(Catalog!I6<>"",Catalog!J6<>""),"; ","")&IF(Catalog!J6="","",Catalog!J6) | D32: =Catalog!P6 -> 0 | E32: =Catalog!R6 -> 0 | F32: =Catalog!M6 -> Bengali | G32: =Catalog!K6 -> Fiction (FIC) | H32: =IF(Catalog!S6<>"","ISBN:"&Catalog!S6,IF(Catalog!T6<>"","ISSN:"&Catalog!T6,"")) | I32: =Catalog!B6 -> ACC-0005 | J32: =Catalog!L6 -> Literature (LIT) | K32: =IF(Catalog!AG6<>"",Catalog!AG6,Catalog!AE6) -> 0 | L32: =Catalog!AD6 -> 0 | M32: =Catalog!V6 -> 0 | N32: =Catalog!Q6 -> 0 | O32: =Catalog!AF6 -> 0
A33: =Catalog!D7 -> Rabindra Rachanabali | B33: =Catalog!F7 -> Rabindranath Tagore | C33: =IF(Catalog!I7="","",Catalog!I7)&IF(AND(Catalog!I7<>"",Catalog!J7<>""),"; ","")&IF(Catalog!J7="","",Catalog!J7) | D33: =Catalog!P7 -> 0 | E33: =Catalog!R7 -> 0 | F33: =Catalog!M7 -> Bengali | G33: =Catalog!K7 -> Fiction (FIC) | H33: =IF(Catalog!S7<>"","ISBN:"&Catalog!S7,IF(Catalog!T7<>"","ISSN:"&Catalog!T7,"")) | I33: =Catalog!B7 -> ACC-0006 | J33: =Catalog!L7 -> Literature (LIT) | K33: =IF(Catalog!AG7<>"",Catalog!AG7,Catalog!AE7) -> 0 | L33: =Catalog!AD7 -> 0 | M33: =Catalog!V7 -> 0 | N33: =Catalog!Q7 -> 0 | O33: =Catalog!AF7 -> 0
A34: =Catalog!D8 -> Rabindra Rachanabali | B34: =Catalog!F8 -> Rabindranath Tagore | C34: =IF(Catalog!I8="","",Catalog!I8)&IF(AND(Catalog!I8<>"",Catalog!J8<>""),"; ","")&IF(Catalog!J8="","",Catalog!J8) | D34: =Catalog!P8 -> 0 | E34: =Catalog!R8 -> 0 | F34: =Catalog!M8 -> Bengali | G34: =Catalog!K8 -> Fiction (FIC) | H34: =IF(Catalog!S8<>"","ISBN:"&Catalog!S8,IF(Catalog!T8<>"","ISSN:"&Catalog!T8,"")) | I34: =Catalog!B8 -> ACC-0007 | J34: =Catalog!L8 -> Literature (LIT) | K34: =IF(Catalog!AG8<>"",Catalog!AG8,Catalog!AE8) -> 0 | L34: =Catalog!AD8 -> 0 | M34: =Catalog!V8 -> 0 | N34: =Catalog!Q8 -> 0 | O34: =Catalog!AF8 -> 0
A35: =Catalog!D9 -> Rabindra Rachanabali | B35: =Catalog!F9 -> Rabindranath Tagore | C35: =IF(Catalog!I9="","",Catalog!I9)&IF(AND(Catalog!I9<>"",Catalog!J9<>""),"; ","")&IF(Catalog!J9="","",Catalog!J9) | D35: =Catalog!P9 -> 0 | E35: =Catalog!R9 -> 0 | F35: =Catalog!M9 -> Bengali | G35: =Catalog!K9 -> Fiction (FIC) | H35: =IF(Catalog!S9<>"","ISBN:"&Catalog!S9,IF(Catalog!T9<>"","ISSN:"&Catalog!T9,"")) | I35: =Catalog!B9 -> ACC-0008 | J35: =Catalog!L9 -> Literature (LIT) | K35: =IF(Catalog!AG9<>"",Catalog!AG9,Catalog!AE9) -> 0 | L35: =Catalog!AD9 -> 0 | M35: =Catalog!V9 -> 0 | N35: =Catalog!Q9 -> 0 | O35: =Catalog!AF9 -> 0
A36: =Catalog!D10 -> Rabindra Rachanabali | B36: =Catalog!F10 -> Rabindranath Tagore | C36: =IF(Catalog!I10="","",Catalog!I10)&IF(AND(Catalog!I10<>"",Catalog!J10<>""),"; ","")&IF(Catalog!J10="","",Catalog!J10) | D36: =Catalog!P10 -> 0 | E36: =Catalog!R10 -> 0 | F36: =Catalog!M10 -> Bengali | G36: =Catalog!K10 -> Fiction (FIC) | H36: =IF(Catalog!S10<>"","ISBN:"&Catalog!S10,IF(Catalog!T10<>"","ISSN:"&Catalog!T10,"")) | I36: =Catalog!B10 -> ACC-0009 | J36: =Catalog!L10 -> Literature (LIT) | K36: =IF(Catalog!AG10<>"",Catalog!AG10,Catalog!AE10) -> 0 | L36: =Catalog!AD10 -> 0 | M36: =Catalog!V10 -> 0 | N36: =Catalog!Q10 -> 0 | O36: =Catalog!AF10 -> 0
A37: =Catalog!D11 -> Rabindra Rachanabali | B37: =Catalog!F11 -> Rabindranath Tagore | C37: =IF(Catalog!I11="","",Catalog!I11)&IF(AND(Catalog!I11<>"",Catalog!J11<>""),"; ","")&IF(Catalog!J11="","",Catalog!J11) | D37: =Catalog!P11 -> 0 | E37: =Catalog!R11 -> 0 | F37: =Catalog!M11 -> Bengali | G37: =Catalog!K11 -> Fiction (FIC) | H37: =IF(Catalog!S11<>"","ISBN:"&Catalog!S11,IF(Catalog!T11<>"","ISSN:"&Catalog!T11,"")) | I37: =Catalog!B11 -> ACC-0010 | J37: =Catalog!L11 -> Literature (LIT) | K37: =IF(Catalog!AG11<>"",Catalog!AG11,Catalog!AE11) -> 0 | L37: =Catalog!AD11 -> 0 | M37: =Catalog!V11 -> 0 | N37: =Catalog!Q11 -> 0 | O37: =Catalog!AF11 -> 0
A38: =Catalog!D12 -> Rabindra Rachanabali | B38: =Catalog!F12 -> Rabindranath Tagore | C38: =IF(Catalog!I12="","",Catalog!I12)&IF(AND(Catalog!I12<>"",Catalog!J12<>""),"; ","")&IF(Catalog!J12="","",Catalog!J12) | D38: =Catalog!P12 -> 0 | E38: =Catalog!R12 -> 0 | F38: =Catalog!M12 -> Bengali | G38: =Catalog!K12 -> Fiction (FIC) | H38: =IF(Catalog!S12<>"","ISBN:"&Catalog!S12,IF(Catalog!T12<>"","ISSN:"&Catalog!T12,"")) | I38: =Catalog!B12 -> ACC-0011 | J38: =Catalog!L12 -> Literature (LIT) | K38: =IF(Catalog!AG12<>"",Catalog!AG12,Catalog!AE12) -> 0 | L38: =Catalog!AD12 -> 0 | M38: =Catalog!V12 -> 0 | N38: =Catalog!Q12 -> 0 | O38: =Catalog!AF12 -> 0
A39: =Catalog!D13 -> Rabindra Rachanabali | B39: =Catalog!F13 -> Rabindranath Tagore | C39: =IF(Catalog!I13="","",Catalog!I13)&IF(AND(Catalog!I13<>"",Catalog!J13<>""),"; ","")&IF(Catalog!J13="","",Catalog!J13) | D39: =Catalog!P13 -> 0 | E39: =Catalog!R13 -> 0 | F39: =Catalog!M13 -> Bengali | G39: =Catalog!K13 -> Fiction (FIC) | H39: =IF(Catalog!S13<>"","ISBN:"&Catalog!S13,IF(Catalog!T13<>"","ISSN:"&Catalog!T13,"")) | I39: =Catalog!B13 -> ACC-0012 | J39: =Catalog!L13 -> Literature (LIT) | K39: =IF(Catalog!AG13<>"",Catalog!AG13,Catalog!AE13) -> 0 | L39: =Catalog!AD13 -> 0 | M39: =Catalog!V13 -> 0 | N39: =Catalog!Q13 -> 0 | O39: =Catalog!AF13 -> 0
... A527: =Catalog!D501 -> 0 | B527: =Catalog!F501 -> 0 | C527: =IF(Catalog!I501="","",Catalog!I501)&IF(AND(Catalog!I501<>"",Catalog!J501<>""),"; ","")&IF(Catalog!J501="","",Catalog!J501) | D527: =Catalog!P501 -> 0 | E527: =Catalog!R501 -> 0 | F527: =Catalog!M501 -> 0 | G527: =Catalog!K501 -> 0 | H527: =IF(Catalog!S501<>"","ISBN:"&Catalog!S501,IF(Catalog!T501<>"","ISSN:"&Catalog!T501,"")) | I527: =Catalog!B501 -> 0 | J527: =Catalog!L501 -> 0 | K527: =IF(Catalog!AG501<>"",Catalog!AG501,Catalog!AE501) -> 0 | L527: =Catalog!AD501 -> 0 | M527: =Catalog!V501 -> 0 | N527: =Catalog!Q501 -> 0 | O527: =Catalog!AF501 -> 0

Sheet Data_Quality
A1: DATA QUALITY REPORT
A3: Metric | B3: Value
A4: Total Catalog records | B4: =COUNTA(Catalog!$D$2:$D$501) -> 20
A5: Records missing Title | B5: =COUNTA(Catalog!$A$2:$A$501)-COUNTA(Catalog!$D$2:$D$501) -> 480
A6: Records missing Creator | B6: =SUMPRODUCT((Catalog!$D$2:$D$501<>"")*(Catalog!$F$2:$F$501="")) -> 1
A7: Records missing Type | B7: =SUMPRODUCT((Catalog!$D$2:$D$501<>"")*(Catalog!$K$2:$K$501="")) -> 0
A8: Records missing Genre | B8: =SUMPRODUCT((Catalog!$D$2:$D$501<>"")*(Catalog!$L$2:$L$501="")) -> 0
A9: Records missing Location Type | B9: =SUMPRODUCT((Catalog!$D$2:$D$501<>"")*(Catalog!$W$2:$W$501="")) -> 0
A10: Records missing Location Identifier | B10: =SUMPRODUCT((Catalog!$D$2:$D$501<>"")*(Catalog!$X$2:$X$501="")) -> 0
A11: Duplicate ISBNs | B11: =SUMPRODUCT((Catalog!$S$2:$S$501<>"")*(COUNTIF(Catalog!$S$2:$S$501,Catalog!$S$2:$S$501)>1))/2 -> 0
A12: Duplicate ISSNs | B12: =SUMPRODUCT((Catalog!$T$2:$T$501<>"")*(COUNTIF(Catalog!$T$2:$T$501,Catalog!$T$2:$T$501)>1))/2 -> 0
A13: Duplicate Accession Numbers | B13: =SUMPRODUCT((Catalog!$B$2:$B$501<>"")*(COUNTIF(Catalog!$B$2:$B$501,Catalog!$B$2:$B$501)>1))/2 -> 0
A14: Digital resources | B14: =COUNTA(Digital_Catalog!$C$2:$C$501) -> 6
A15: Archive objects | B15: =COUNTA(Archive!$B$2:$B$201) -> 2
A16: Active loans | B16: =COUNTIF(Circulation!$H$2:$H$501,"Active") -> 0
A17: Overdue loans | B17: =COUNTIF(Circulation!$H$2:$H$501,"Overdue") -> 0
A25: RECORD-LEVEL CHECKS
A26: Item ID | B26: Title | C26: Issues
A27: =Catalog!A2 -> 1 | B27: =Catalog!D2 -> Rabindra Rachanabali | C27: =IF(Catalog!D2="","",IF(ISBLANK(Catalog!F2),"Missing Creator; ","")&IF(ISBLANK(Catalog!K2),"Missing Type; ","")&IF(ISBLANK(Catalog!L2),"Missing Genre; ","")&IF(ISBLANK(Catalog!W2),"Missing Location Type; ","")&IF(ISBLANK(Catalog!X2),"Missing Location Identifier; ","")&IF(AND(Catalog!S2<>"",COUNTIF(Catalog!$S$2:$S$501,Catalog!S2)>1),"Duplicate ISBN; ","")&IF(AND(Catalog!B2<>"",COUNTIF(Catalog!$B$2:$B$501,Catalog!B2)>1),"Duplicate Accession; ",""))
A28: =Catalog!A3 -> 2 | B28: =Catalog!D3 -> Rabindra Rachanabali | C28: =IF(Catalog!D3="","",IF(ISBLANK(Catalog!F3),"Missing Creator; ","")&IF(ISBLANK(Catalog!K3),"Missing Type; ","")&IF(ISBLANK(Catalog!L3),"Missing Genre; ","")&IF(ISBLANK(Catalog!W3),"Missing Location Type; ","")&IF(ISBLANK(Catalog!X3),"Missing Location Identifier; ","")&IF(AND(Catalog!S3<>"",COUNTIF(Catalog!$S$2:$S$501,Catalog!S3)>1),"Duplicate ISBN; ","")&IF(AND(Catalog!B3<>"",COUNTIF(Catalog!$B$2:$B$501,Catalog!B3)>1),"Duplicate Accession; ",""))
A29: =Catalog!A4 -> 3 | B29: =Catalog!D4 -> Rabindra Rachanabali | C29: =IF(Catalog!D4="","",IF(ISBLANK(Catalog!F4),"Missing Creator; ","")&IF(ISBLANK(Catalog!K4),"Missing Type; ","")&IF(ISBLANK(Catalog!L4),"Missing Genre; ","")&IF(ISBLANK(Catalog!W4),"Missing Location Type; ","")&IF(ISBLANK(Catalog!X4),"Missing Location Identifier; ","")&IF(AND(Catalog!S4<>"",COUNTIF(Catalog!$S$2:$S$501,Catalog!S4)>1),"Duplicate ISBN; ","")&IF(AND(Catalog!B4<>"",COUNTIF(Catalog!$B$2:$B$501,Catalog!B4)>1),"Duplicate Accession; ",""))
A30: =Catalog!A5 -> 4 | B30: =Catalog!D5 -> Rabindra Rachanabali | C30: =IF(Catalog!D5="","",IF(ISBLANK(Catalog!F5),"Missing Creator; ","")&IF(ISBLANK(Catalog!K5),"Missing Type; ","")&IF(ISBLANK(Catalog!L5),"Missing Genre; ","")&IF(ISBLANK(Catalog!W5),"Missing Location Type; ","")&IF(ISBLANK(Catalog!X5),"Missing Location Identifier; ","")&IF(AND(Catalog!S5<>"",COUNTIF(Catalog!$S$2:$S$501,Catalog!S5)>1),"Duplicate ISBN; ","")&IF(AND(Catalog!B5<>"",COUNTIF(Catalog!$B$2:$B$501,Catalog!B5)>1),"Duplicate Accession; ",""))
A31: =Catalog!A6 -> 5 | B31: =Catalog!D6 -> Rabindra Rachanabali | C31: =IF(Catalog!D6="","",IF(ISBLANK(Catalog!F6),"Missing Creator; ","")&IF(ISBLANK(Catalog!K6),"Missing Type; ","")&IF(ISBLANK(Catalog!L6),"Missing Genre; ","")&IF(ISBLANK(Catalog!W6),"Missing Location Type; ","")&IF(ISBLANK(Catalog!X6),"Missing Location Identifier; ","")&IF(AND(Catalog!S6<>"",COUNTIF(Catalog!$S$2:$S$501,Catalog!S6)>1),"Duplicate ISBN; ","")&IF(AND(Catalog!B6<>"",COUNTIF(Catalog!$B$2:$B$501,Catalog!B6)>1),"Duplicate Accession; ",""))
A32: =Catalog!A7 -> 6 | B32: =Catalog!D7 -> Rabindra Rachanabali | C32: =IF(Catalog!D7="","",IF(ISBLANK(Catalog!F7),"Missing Creator; ","")&IF(ISBLANK(Catalog!K7),"Missing Type; ","")&IF(ISBLANK(Catalog!L7),"Missing Genre; ","")&IF(ISBLANK(Catalog!W7),"Missing Location Type; ","")&IF(ISBLANK(Catalog!X7),"Missing Location Identifier; ","")&IF(AND(Catalog!S7<>"",COUNTIF(Catalog!$S$2:$S$501,Catalog!S7)>1),"Duplicate ISBN; ","")&IF(AND(Catalog!B7<>"",COUNTIF(Catalog!$B$2:$B$501,Catalog!B7)>1),"Duplicate Accession; ",""))
A33: =Catalog!A8 -> 7 | B33: =Catalog!D8 -> Rabindra Rachanabali | C33: =IF(Catalog!D8="","",IF(ISBLANK(Catalog!F8),"Missing Creator; ","")&IF(ISBLANK(Catalog!K8),"Missing Type; ","")&IF(ISBLANK(Catalog!L8),"Missing Genre; ","")&IF(ISBLANK(Catalog!W8),"Missing Location Type; ","")&IF(ISBLANK(Catalog!X8),"Missing Location Identifier; ","")&IF(AND(Catalog!S8<>"",COUNTIF(Catalog!$S$2:$S$501,Catalog!S8)>1),"Duplicate ISBN; ","")&IF(AND(Catalog!B8<>"",COUNTIF(Catalog!$B$2:$B$501,Catalog!B8)>1),"Duplicate Accession; ",""))
A34: =Catalog!A9 -> 8 | B34: =Catalog!D9 -> Rabindra Rachanabali | C34: =IF(Catalog!D9="","",IF(ISBLANK(Catalog!F9),"Missing Creator; ","")&IF(ISBLANK(Catalog!K9),"Missing Type; ","")&IF(ISBLANK(Catalog!L9),"Missing Genre; ","")&IF(ISBLANK(Catalog!W9),"Missing Location Type; ","")&IF(ISBLANK(Catalog!X9),"Missing Location Identifier; ","")&IF(AND(Catalog!S9<>"",COUNTIF(Catalog!$S$2:$S$501,Catalog!S9)>1),"Duplicate ISBN; ","")&IF(AND(Catalog!B9<>"",COUNTIF(Catalog!$B$2:$B$501,Catalog!B9)>1),"Duplicate Accession; ",""))
A35: =Catalog!A10 -> 9 | B35: =Catalog!D10 -> Rabindra Rachanabali | C35: =IF(Catalog!D10="","",IF(ISBLANK(Catalog!F10),"Missing Creator; ","")&IF(ISBLANK(Catalog!K10),"Missing Type; ","")&IF(ISBLANK(Catalog!L10),"Missing Genre; ","")&IF(ISBLANK(Catalog!W10),"Missing Location Type; ","")&IF(ISBLANK(Catalog!X10),"Missing Location Identifier; ","")&IF(AND(Catalog!S10<>"",COUNTIF(Catalog!$S$2:$S$501,Catalog!S10)>1),"Duplicate ISBN; ","")&IF(AND(Catalog!B10<>"",COUNTIF(Catalog!$B$2:$B$501,Catalog!B10)>1),"Duplicate Accession; ",""))
A36: =Catalog!A11 -> 10 | B36: =Catalog!D11 -> Rabindra Rachanabali | C36: =IF(Catalog!D11="","",IF(ISBLANK(Catalog!F11),"Missing Creator; ","")&IF(ISBLANK(Catalog!K11),"Missing Type; ","")&IF(ISBLANK(Catalog!L11),"Missing Genre; ","")&IF(ISBLANK(Catalog!W11),"Missing Location Type; ","")&IF(ISBLANK(Catalog!X11),"Missing Location Identifier; ","")&IF(AND(Catalog!S11<>"",COUNTIF(Catalog!$S$2:$S$501,Catalog!S11)>1),"Duplicate ISBN; ","")&IF(AND(Catalog!B11<>"",COUNTIF(Catalog!$B$2:$B$501,Catalog!B11)>1),"Duplicate Accession; ",""))
A37: =Catalog!A12 -> 11 | B37: =Catalog!D12 -> Rabindra Rachanabali | C37: =IF(Catalog!D12="","",IF(ISBLANK(Catalog!F12),"Missing Creator; ","")&IF(ISBLANK(Catalog!K12),"Missing Type; ","")&IF(ISBLANK(Catalog!L12),"Missing Genre; ","")&IF(ISBLANK(Catalog!W12),"Missing Location Type; ","")&IF(ISBLANK(Catalog!X12),"Missing Location Identifier; ","")&IF(AND(Catalog!S12<>"",COUNTIF(Catalog!$S$2:$S$501,Catalog!S12)>1),"Duplicate ISBN; ","")&IF(AND(Catalog!B12<>"",COUNTIF(Catalog!$B$2:$B$501,Catalog!B12)>1),"Duplicate Accession; ",""))
A38: =Catalog!A13 -> 12 | B38: =Catalog!D13 -> Rabindra Rachanabali | C38: =IF(Catalog!D13="","",IF(ISBLANK(Catalog!F13),"Missing Creator; ","")&IF(ISBLANK(Catalog!K13),"Missing Type; ","")&IF(ISBLANK(Catalog!L13),"Missing Genre; ","")&IF(ISBLANK(Catalog!W13),"Missing Location Type; ","")&IF(ISBLANK(Catalog!X13),"Missing Location Identifier; ","")&IF(AND(Catalog!S13<>"",COUNTIF(Catalog!$S$2:$S$501,Catalog!S13)>1),"Duplicate ISBN; ","")&IF(AND(Catalog!B13<>"",COUNTIF(Catalog!$B$2:$B$501,Catalog!B13)>1),"Duplicate Accession; ",""))
... A526: =Catalog!A501 | B526: =Catalog!D501 -> 0 | C526: =IF(Catalog!D501="","",IF(ISBLANK(Catalog!F501),"Missing Creator; ","")&IF(ISBLANK(Catalog!K501),"Missing Type; ","")&IF(ISBLANK(Catalog!L501),"Missing Genre; ","")&IF(ISBLANK(Catalog!W501),"Missing Location Type; ","")&IF(ISBLANK(Catalog!X501),"Missing Location Identifier; ","")&IF(AND(Catalog!S501<>"",COUNTIF(Catalog!$S$2:$S$501,Catalog!S501)>1),"Duplicate ISBN; ","")&IF(AND(Catalog!B501<>"",COUNTIF(Catalog!$B$2:$B$501,Catalog!B501)>1),"Duplicate Accession; ",""))

Sheet Dashboard
B2: PERSONAL LIBRARY MANAGER & DIGITAL ARCHIVE — DASHBOARD
B4: COLLECTION | E4: METADATA
B5: Physical items | C5: =COUNTA(Catalog!A2:A501) -> 500 | E5: Missing titles | F5: =COUNTA(Catalog!A2:A501)-COUNTA(Catalog!D2:D501) -> 480
B6: Digital resources | C6: =COUNTA(Digital_Catalog!A2:A501) -> 500 | E6: Missing creators | F6: =SUMPRODUCT((Catalog!D2:D501<>"")*(Catalog!F2:F501="")) -> 1
B7: Archive objects | C7: =COUNTA(Archive!A2:A201) -> 200 | E7: Missing locations | F7: =SUMPRODUCT((Catalog!D2:D501<>"")*(Catalog!W2:W501="")) -> 0
B8: Books | C8: =COUNTIF(Catalog!K2:K501,"Book") -> 0 | E8: Duplicate ISBNs | F8: =SUMPRODUCT((Catalog!S2:S501<>"")*(COUNTIF(Catalog!S2:S501,Catalog!S2:S501)>1))/2 -> 0
B9: Magazines | C9: =COUNTIF(Catalog!K2:K501,"Magazine") -> 1 | E9: Duplicate Accessions | F9: =SUMPRODUCT((Catalog!B2:B501<>"")*(COUNTIF(Catalog!B2:B501,Catalog!B2:B501)>1))/2 -> 0
B10: Journals | C10: =COUNTIF(Catalog!K2:K501,"Journal") -> 0
B11: Other materials | C11: =COUNTA(Catalog!A2:A501)-COUNTIF(Catalog!K2:K501,"Book")-COUNTIF(Catalog!K2:K501,"Magazine")-COUNTIF(Catalog!K2:K501,"Journal") -> 499
B14: READING STATUS | E14: CIRCULATION
B15: Read | C15: =COUNTIF(Digital_Catalog!Z2:Z501,"Read") -> 1 | E15: Available | F15: =COUNTIF(Catalog!Z2:Z501,"Available") -> 20
